<?xml version="1.6"?>

<robot xmlns:xacro="http://www.ros.org/wiki/xacro" name="barista_robot" xmlns:xsi="http://www.w3.org/2001/XMLSchema-instance"
       xsi:schemaLocation="http://www.ros.org/wiki/xacro">

    <xacro:property name="robot_name" value="$(arg robot_name)"/>

    <xacro:include filename="$(find barista_robot_description)/xacro/wheel.xacro"/>
    <xacro:include filename="$(find barista_robot_description)/xacro/standoff.xacro"/>
    <xacro:include filename="$(find barista_robot_description)/xacro/cup_holder_tray.xacro"/>

    <material name="red">
        <color rgba="1.0 0.0 0.0 1"/>
    </material>
    <material name="green_light">
        <color rgba="0.0 1.0 0.0 1"/>
    </material>
    <material name="green_dark">
        <color rgba="0.0 0.5 0.0 1"/>
    </material>

    <material name="blue">
        <color rgba="0.0 0.0 1.0 1.0"/>
    </material>

    <material name="light_gray">
        <color rgba="0.83 0.83 0.83 1.0"/>
    </material>

    <material name="black">
        <color rgba="0.0 0.0 0.0 1.0"/>
    </material>

    <xacro:if value="${robot_name == 'morty'}">
        <xacro:property name="rviz_color" value="red"/>
        <xacro:property name="rviz_wheel_color" value="blue"/>
        <xacro:property name="gazebo_color" value="Gazebo/Red"/>
        <xacro:property name="gazebo_wheel_color" value="Gazebo/Blue"/>
    </xacro:if>
    <xacro:unless value="${robot_name == 'morty'}">
        <xacro:property name="rviz_color" value="blue"/>
        <xacro:property name="rviz_wheel_color" value="red"/>
        <xacro:property name="gazebo_color" value="Gazebo/Blue"/>
        <xacro:property name="gazebo_wheel_color" value="Gazebo/Red"/>
    </xacro:unless>

    <xacro:property name="caster_rviz_color" value="green_light"/>
    <xacro:property name="caster_gazebo_color" value="Gazebo/Yellow"/>

    <link name="base_link"/>

    <link name="main_body_link">
        <visual>
            <origin rpy="0 0 0" xyz="0 0 0"/>
            <geometry>
                <cylinder length="0.155" radius="0.178"/>
            </geometry>
            <material name="${rviz_color}"/>
        </visual>
        <collision>
            <origin rpy="0 0 0" xyz="0 0 0"/>
            <geometry>
                <cylinder length="0.155" radius="0.178"/>
            </geometry>
        </collision>
        <inertial>
            <mass value="5.0"/>
            <origin rpy="0 0 0" xyz="0 0 0"/>
            <inertia ixx="0.049615416666666667" ixy="0.0" ixz="0.0" iyy="0.049615416666666667" iyz="0.0" izz="0.07920999999999999"/>
        </inertial>
    </link>

    <joint name="base_link_joint" type="fixed">
        <origin rpy="0 0 0" xyz="0 0 0"/>
        <parent link="base_link"/>
        <child link="main_body_link"/>
        <axis xyz="0 0 0"/>
    </joint>

    <gazebo reference="main_body_link">
        <material>${gazebo_color}</material>
    </gazebo>


    <xacro:wheel wheel_name="left_wheel"/>
    <joint name="left_wheel_joint" type="continuous">
        <origin rpy="0.0 0.0 0.0" xyz="0.0 0.13 -0.07"/>
        <parent link="main_body_link"/>
        <child link="left_wheel"/>
        <axis xyz="0 1 0" rpy="0 0 0"/>
    </joint>

    <gazebo reference="left_wheel">
        <kp>1000000000000000000000000000.0</kp>
        <kd>1000000000000000000000000000.0</kd>
        <mu1>10.0</mu1>
        <mu2>10.0</mu2>
        <material>${gazebo_wheel_color}</material>
    </gazebo>


    <xacro:wheel wheel_name="right_wheel"/>
    <joint name="right_wheel_joint" type="continuous">
        <origin rpy="0.0 0.0 0.0" xyz="0.0 -0.13 -0.07"/>
        <parent link="main_body_link"/>
        <child link="right_wheel"/>
        <axis xyz="0 1 0" rpy="0 0 0"/>
    </joint>

    <gazebo reference="right_wheel">
        <kp>1000000000000000000000000000.0</kp>
        <kd>1000000000000000000000000000.0</kd>
        <mu1>10.0</mu1>
        <mu2>10.0</mu2>
        <material>${gazebo_wheel_color}</material>
    </gazebo>


    <!-- Casters -->
    <!-- Caster Wheel Front -->
    <link name="front_yaw_link">
        <visual>
            <origin rpy="0 1.5707 1.5707" xyz="0.0 0 0.0"/>
            <geometry>
                <cylinder length="0.015" radius="0.02"/>
            </geometry>
            <material name="${caster_rviz_color}"/>
        </visual>

        <collision>
            <origin rpy="0 1.5707 1.5707" xyz="0.0 0 0.0"/>
            <geometry>
                <cylinder length="0.015" radius="0.02"/>
            </geometry>
        </collision>

        <inertial>
            <origin rpy="0 1.5707 1.5707" xyz="0.0 0 0.0"/>
            <mass value="0.05"/>
            <inertia ixx="5.9375e-06" ixy="0.0" ixz="0.0" iyy="5.9375e-06" iyz="0.0" izz="1e-05"/>
        </inertial>
    </link>

    <joint name="front_yaw_joint" type="continuous">
        <origin rpy="0 0 0" xyz="0.13 0 -0.079"/>
        <parent link="main_body_link"/>
        <child link="front_yaw_link"/>
        <axis xyz="0 0 1"/>
    </joint>

    <gazebo reference="front_yaw_link">
        <material>${caster_gazebo_color}</material>
    </gazebo>

    <link name="front_roll_link">
        <visual>
            <origin rpy="0 1.5707 1.5707" xyz="0 0 0"/>
            <geometry>
                <cylinder length="0.015" radius="0.02"/>
            </geometry>
            <material name="${caster_rviz_color}"/>
        </visual>

        <collision>
            <origin rpy="0 1.5707 1.5707" xyz="0 0 0"/>
            <geometry>
                <cylinder length="0.015" radius="0.02"/>
            </geometry>
        </collision>

        <inertial>
            <origin rpy="0 1.5707 1.5707" xyz="0 0 0"/>
            <mass value="0.05"/>
            <inertia ixx="5.9375e-06" ixy="0.0" ixz="0.0" iyy="5.9375e-06" iyz="0.0" izz="1e-05"/>
        </inertial>
    </link>

    <joint name="front_roll_joint" type="continuous">
        <origin rpy="0 0 0" xyz="0 0 0"/>
        <parent link="front_yaw_link"/>
        <child link="front_roll_link"/>
        <axis xyz="1 0 0"/>
    </joint>

    <gazebo reference="front_roll_link">
        <material>${caster_gazebo_color}</material>
    </gazebo>


    <link name="front_pitch_link">
        <visual>
            <origin rpy="0 1.5707 1.5707" xyz="0 0 0"/>
            <geometry>
                <sphere radius="0.025"/>
            </geometry>
            <material name="${caster_rviz_color}"/>
        </visual>

        <collision>
            <origin rpy="0 1.5707 1.5707" xyz="0 0 0"/>
            <geometry>
                <sphere radius="0.025"/>
            </geometry>
        </collision>

        <inertial>
            <origin rpy="0 1.5707 1.5707" xyz="0 0 0"/>
            <mass value="0.05"/>
            <inertia ixx="1.2500000000000002e-05" ixy="0.0" ixz="0.0" iyy="1.2500000000000002e-05" iyz="0.0" izz="1.2500000000000002e-05"/>
        </inertial>
    </link>

    <gazebo reference="front_pitch_link">
        <kp>1000000000000000000000000000.0</kp>
        <kd>1000000000000000000000000000.0</kd>
        <mu1>0.5</mu1>
        <mu2>0.5</mu2>
        <material>${caster_gazebo_color}</material>
    </gazebo>

    <joint name="front_pitch_joint" type="continuous">
        <origin rpy="0 0 0" xyz="0 0 0"/>
        <parent link="front_roll_link"/>
        <child link="front_pitch_link"/>
        <axis xyz="0 1 0"/>
    </joint>

    <!-- Caster Wheel Back -->
    <link name="back_yaw_link">
        <visual>
            <origin rpy="0 1.5707 1.5707" xyz="0.0 0.0 0.0"/>
            <geometry>
                <cylinder length="0.015" radius="0.02"/>
            </geometry>
            <material name="${caster_rviz_color}"/>
        </visual>

        <collision>
            <origin rpy="0 1.5707 1.5707" xyz="0.0 0.0 0.0"/>
            <geometry>
                <cylinder length="0.015" radius="0.02"/>
            </geometry>
        </collision>

        <inertial>
            <origin rpy="0 1.5707 1.5707" xyz="0.0 0.0 0.0"/>
            <mass value="0.05"/>
            <inertia ixx="5.9375e-06" ixy="0.0" ixz="0.0" iyy="5.9375e-06" iyz="0.0" izz="1e-05"/>
        </inertial>
    </link>

    <joint name="back_yaw_joint" type="continuous">
        <origin rpy="0 0 0" xyz="-0.13 0 -0.079"/>
        <parent link="main_body_link"/>
        <child link="back_yaw_link"/>
        <axis xyz="0 0 1"/>
    </joint>

    <gazebo reference="back_yaw_link">
        <material>${caster_gazebo_color}</material>
    </gazebo>

    <link name="back_roll_link">
        <visual>
            <origin rpy="0 1.5707 1.5707" xyz="0 0 0"/>
            <geometry>
                <cylinder length="0.015" radius="0.02"/>
            </geometry>
            <material name="${caster_rviz_color}"/>
        </visual>

        <collision>
            <origin rpy="0 1.5707 1.5707" xyz="0 0 0"/>
            <geometry>
                <cylinder length="0.015" radius="0.02"/>
            </geometry>
        </collision>

        <inertial>
            <origin rpy="0 1.5707 1.5707" xyz="0 0 0"/>
            <mass value="0.05"/>
            <inertia ixx="5.9375e-06" ixy="0.0" ixz="0.0" iyy="5.9375e-06" iyz="0.0" izz="1e-05"/>
        </inertial>
    </link>

    <joint name="back_roll_joint" type="continuous">
        <origin rpy="0 0 0" xyz="0 0 0"/>
        <parent link="back_yaw_link"/>
        <child link="back_roll_link"/>
        <axis xyz="1 0 0"/>
    </joint>

    <gazebo reference="back_roll_link">
        <material>${caster_gazebo_color}</material>
    </gazebo>


    <link name="back_pitch_link">
        <visual>
            <origin rpy="0 1.5707 1.5707" xyz="0 0 0"/>
            <geometry>
                <sphere radius="0.025"/>
            </geometry>
            <material name="${caster_rviz_color}"/>
        </visual>

        <collision>
            <origin rpy="0 1.5707 1.5707" xyz="0 0 0"/>
            <geometry>
                <sphere radius="0.025"/>
            </geometry>
        </collision>

        <inertial>
            <origin rpy="0 1.5707 1.5707" xyz="0 0 0"/>
            <mass value="0.05"/>
            <inertia ixx="1.2500000000000002e-05" ixy="0.0" ixz="0.0" iyy="1.2500000000000002e-05" iyz="0.0" izz="1.2500000000000002e-05"/>
        </inertial>
    </link>

    <gazebo reference="back_pitch_link">
        <kp>1000000000000000000000000000.0</kp>
        <kd>1000000000000000000000000000.0</kd>
        <mu1>0.5</mu1>
        <mu2>0.5</mu2>
        <material>${caster_gazebo_color}</material>
    </gazebo>

    <joint name="back_pitch_joint" type="continuous">
        <origin rpy="0 0 0" xyz="0 0 0"/>
        <parent link="back_roll_link"/>
        <child link="back_pitch_link"/>
        <axis xyz="0 1 0"/>
    </joint>

        <!-- standoff_rods -->
        <link name="standoff_rods">
            <xacro:standoff x_pos="0.106" y_pos="0.106"/>
            <xacro:standoff x_pos="-0.106" y_pos="0.106"/>
            <xacro:standoff x_pos="-0.106" y_pos="-0.106"/>
            <xacro:standoff x_pos="0.106" y_pos="-0.106"/>
    
            <inertial>
                <mass value="0.4"/>
                <origin rpy="0 0 0" xyz="0 0 0"/>
                <inertia ixx="0.004226666666666668" ixy="0.0" ixz="0.0" iyy="0.0019466666666666666" iyz="0.0" izz="0.002946666666666667"/>
            </inertial>
        </link>
    
        <joint name="body_to_standoff_rods_joint" type="fixed">
            <origin rpy="0 0 0" xyz="0.0 0.0 0.1875"/>        
            <parent link="main_body_link"/>
            <child link="standoff_rods"/>
        </joint>
    
        <xacro:cup_holder_tray/>
        <joint name="standoff_rods_to_tray_joint" type="fixed">
            <origin rpy="0 0 0" xyz="0 0 0.155"/>
            <parent link="standoff_rods"/>
            <child link="cup_holder"/>        
        </joint>
    
        <gazebo reference="cup_holder">
            <material>${gazebo_color}</material>
        </gazebo>
    
        <!-- Laser scanner (conditional) -->
        <xacro:arg name="include_laser" default="true"/>
    
        <xacro:if value="$(arg include_laser)">
            <xacro:include filename="$(find barista_robot_description)/xacro/laser_scanner.xacro"/>
            <xacro:laser_scanner/>
        </xacro:if>
        <gazebo reference="laser_scanner_model">
            <material>${gazebo_color}</material>
        </gazebo> 

    <!-- PLUGINS -->
    <!-- JOINT PUBLISHER -->
    <gazebo>
        <plugin name="barista_gazebo_${robot_name}_joint_state" filename="libgazebo_ros_joint_state_publisher.so">
            <ros>
                <namespace>/${robot_name}</namespace>
                <remapping>~/out:=joint_states</remapping>
            </ros>
            <update_rate>30</update_rate>

            <joint_name>left_wheel_joint</joint_name>
            <joint_name>right_wheel_joint</joint_name>
            <joint_name>front_yaw_joint</joint_name>
            <joint_name>back_yaw_joint</joint_name>
            <joint_name>front_roll_joint</joint_name>
            <joint_name>back_roll_joint</joint_name>
            <joint_name>front_pitch_joint</joint_name>
            <joint_name>back_pitch_joint</joint_name>
        </plugin>
    </gazebo>

    <!-- Differential drive -->
    <gazebo>
        <plugin filename="libgazebo_ros_diff_drive.so" name="differential_${robot_name}_drive_controller">
            <!-- namespace for multiple robots from the same model-->
            <ros>
                <namespace>/${robot_name}</namespace>
                <remapping>/cmd_vel:=cmd_vel</remapping>
            </ros>

            <!-- wheels -->
            <left_joint>left_wheel_joint</left_joint>
            <right_joint>right_wheel_joint</right_joint>

            <!-- kinematics -->
            <wheel_separation>0.2806</wheel_separation>
            <wheel_diameter>0.0704</wheel_diameter>

            <!-- limits -->
            <max_wheel_torque>200.0</max_wheel_torque>
            <max_wheel_acceleration>10.0</max_wheel_acceleration>

            <!-- input -->
            <!--<command_topic>cmd_vel</command_topic>-->
            
            <!-- output -->
            <publish_odom>true</publish_odom>
            <publish_odom_tf>true</publish_odom_tf>
            <!--<publish_wheel_tf>true</publish_wheel_tf>-->
            
            <odometry_topic>${robot_name}/odom</odometry_topic>
            <odometry_frame>${robot_name}/odom</odometry_frame>
            <robot_base_frame>${robot_name}/base_link</robot_base_frame>

        </plugin>
    </gazebo>
</robot>
