<?xml version="1.6"?>
<robot name="barista_robot">
    <material name="red">
        <color rgba="1.0 0.0 0.0 1"/>
    </material>
    <material name="green_light">
        <color rgba="0.0 1.0 0.0 1"/>
    </material>
    <material name="green_dark">
        <color rgba="0.0 0.5 0.0 1"/>
    </material>
    <material name="blue">
        <color rgba="0.0 0.0 1.0 1"/>
    </material>

    <material name="light_gray">
        <color rgba="0.83 0.83 0.83 1.0"/>
    </material>

    <material name="black">
        <color rgba="0.0 0.0 0.0 1.0"/>
    </material>
    
    <link name="base_link">
    </link>

    <link name="main_body_link">
        <visual>
            <origin rpy="0 0 0" xyz="0 0 0"/>
            <geometry>
                <cylinder length="0.155" radius="0.178"/>
            </geometry>
            <material name="blue"/>
        </visual>
        <collision>
            <origin rpy="0 0 0" xyz="0 0 0"/>
            <geometry>
                <cylinder length="0.155" radius="0.178"/>
            </geometry>
        </collision>
        <inertial>
            <mass value="5.0"/>
            <origin rpy="0 0 0" xyz="0 0 0"/>
            <inertia ixx="0.049615416666666667" ixy="0.0" ixz="0.0" iyy="0.049615416666666667" iyz="0.0" izz="0.07920999999999999"/>
        </inertial>
    </link>

    <gazebo reference="main_body_link">
        <material>Gazebo/Blue</material>
    </gazebo>

    <joint name="base_link_joint" type="fixed">
        <origin rpy="0 0 0" xyz="0 0 0.0"/>
        <parent link="base_link"/>
        <child link="main_body_link"/>
    </joint>

    <!-- standoff_rods -->
    <link name="standoff_rods">
        <!-- visual -->
        <visual>
            <origin rpy="0.0 0.0 0.0" xyz="0.089 0.089 0.0"/>
            <geometry>
                <cylinder length="0.22" radius="0.01"/>
            </geometry>
            <material name="light_gray"/>
        </visual>

        <visual>
            <origin rpy="0.0 0.0 0.0" xyz="-0.089 0.089 0.0"/>
            <geometry>
                <cylinder length="0.22" radius="0.01"/>
            </geometry>
            <material name="light_gray"/>
        </visual>

        <visual>
            <origin rpy="0.0 0.0 0.0" xyz="-0.089 -0.089 0.0"/>
            <geometry>
                <cylinder length="0.22" radius="0.01"/>
            </geometry>
            <material name="light_gray"/>
        </visual>

        <visual>
            <origin rpy="0.0 0.0 0.0" xyz="0.089 -0.089 0.0"/>
            <geometry>
                <cylinder length="0.22" radius="0.01"/>
            </geometry>
            <material name="light_gray"/>
        </visual>

        <!-- collision -->
        <collision>
            <origin rpy="0.0 0.0 0.0" xyz="0.089 0.089 0.0"/>
            <geometry>
                <cylinder length="0.22" radius="0.01"/>
            </geometry>
        </collision>

        <collision>
            <origin rpy="0.0 0.0 0.0" xyz="-0.089 0.089 0.0"/>
            <geometry>
                <cylinder length="0.22" radius="0.01"/>
            </geometry>
        </collision>
        <collision>
            <origin rpy="0.0 0.0 0.0" xyz="-0.089 -0.089 0.0"/>
            <geometry>
                <cylinder length="0.22" radius="0.01"/>
            </geometry>
        </collision>

        <collision>
            <origin rpy="0.0 0.0 0.0" xyz="0.089 -0.089 0.0"/>
            <geometry>
                <cylinder length="0.22" radius="0.01"/>
            </geometry>
        </collision>

        <!-- inertial -->
        <inertial>
            <mass value="0.4"/>
            <origin rpy="0 0 0" xyz="0 0 0"/>
            <inertia ixx="0.004226666666666668" ixy="0.0" ixz="0.0" iyy="0.0019466666666666666" iyz="0.0" izz="0.002946666666666667"/>
        </inertial>
    </link>

    <joint name="body_to_standoff_rods_joint" type="fixed">
        <origin rpy="0 0 0" xyz="0.0 0.0 0.1875"/>
        <parent link="main_body_link"/>
        <child link="standoff_rods"/>
    </joint>


    <!-- CupHolder Tray -->
    <link name="cup_holder_tray">
        <visual>
            <origin xyz="0 0 0" rpy="0 0 0"/>
            <geometry>
                <cylinder length="0.09" radius="0.16"/>
            </geometry>
            <material name="blue"/>
        </visual>
        <collision>
            <origin rpy="0 0 0" xyz="0 0 0"/>
            <geometry>
                <cylinder length="0.09" radius="0.16"/>
            </geometry>
        </collision>
        <inertial>
            <mass value="1.0"/>
            <origin rpy="0 0 0" xyz="0 0 0"/>
            <inertia ixx="0.007075" ixy="0.0" ixz="0.0" iyy="0.007075" iyz="0.0" izz="0.0128"/>
        </inertial>
    </link>

    <gazebo reference="cup_holder_tray">
        <material>Gazebo/Blue</material>
    </gazebo>

    <joint name="standoff_rods_to_tray_joint" type="fixed">
        <origin rpy="0 0 0" xyz="0 0 0.155"/>
        <parent link="standoff_rods"/>
        <child link="cup_holder_tray"/>
    </joint>

    <!-- Wheels -->
    <!-- Wheel Left -->
    <link name="left_wheel">
        <visual>
            <origin rpy="1.5707 0.0 0.0" xyz="0 0 0"/>
            <geometry>  
                <cylinder length="0.0206" radius="0.0352"/>
            </geometry>
            <material name="red"/>
        </visual>

        <collision>
            <origin rpy="1.5707 0.0 0.0" xyz="0 0 0"/>
            <geometry>
                <cylinder length="0.0206" radius="0.0352"/>
            </geometry>
        </collision>

        <inertial>
            <origin rpy="1.5707 0.0 0.0" xyz="0 0 0"/>
            <mass value="0.5"/>
            <inertia ixx="0.00017256166666666667" ixy="0.0" ixz="0.0" iyy="0.00017256166666666667" iyz="0.0" izz="0.00030976"/> 
        </inertial>
    </link>
    
    <gazebo reference="left_wheel">
        <kp>1000000000000000000000000000.0</kp>
        <kd>1000000000000000000000000000.0</kd>
        <mu1>10.0</mu1>
        <mu2>10.0</mu2>        
        <material>Gazebo/Red</material>
    </gazebo>

    <joint name="left_wheel_joint" type="continuous">
        <origin rpy="0.0 0.0 0.0" xyz="0.0024 0.13 -0.07"/>
        <parent link="main_body_link"/>
        <child link="left_wheel"/>
        <axis xyz="0 1 0"/>
        <limit effort="10000" velocity="1000.0"/>
        <dynamics damping="1.0" friction="2.0"/>
    </joint>



    <!-- Right_Wheels -->
    <link name="right_wheel">
        <visual>
            <origin rpy="1.5707 0.0 0.0" xyz="0 0 0"/>
            <geometry>
                <cylinder length="0.0206" radius="0.0352"/>
            </geometry>
            <material name="red"/>
        </visual>
        <collision>
            <origin rpy="1.5707 0.0 0.0" xyz="0 0 0"/>
            <geometry>
                <cylinder length="0.0206" radius="0.0352"/>
            </geometry>
        </collision>
        <inertial>
            <origin rpy="1.5707 0.0 0.0" xyz="0 0 0"/>
            <mass value="0.5"/>
            <inertia ixx="0.00017256166666666667" ixy="0.0" ixz="0.0" iyy="0.00017256166666666667" iyz="0.0" izz="0.00030976"/>    
            <!--<mass value="0.08"/>-->
            <!--<inertia ixx="2.760986666666667e-05" ixy="0.0" ixz="0.0" iyy="2.760986666666667e-05" iyz="0.0" izz="4.95616e-05"/>-->
        </inertial>
    </link>

    <gazebo reference="right_wheel">
        <kp>1000000000000000000000000000.0</kp>
        <kd>1000000000000000000000000000.0</kd>
        <mu1>10.0</mu1>
        <mu2>10.0</mu2>        
        <material>Gazebo/Red</material>
    </gazebo>

    <joint name="right_wheel_joint" type="continuous">
        <origin rpy="0 0 0" xyz="0.0024 -0.13 -0.07"/>
        <parent link="main_body_link"/>
        <child link="right_wheel"/>
        <axis xyz="0 1 0"/>
        <limit effort="10000" velocity="1000.0"/>
        <dynamics damping="1.0" friction="2.0"/>
    </joint>



    <!-- Casters -->
    <!-- Caster Wheel Front -->
    <link name="front_yaw_link">
        <visual>
            <origin rpy="0 1.5707 1.5707" xyz="0.0 0 0.0"/>
            <geometry>
                <cylinder length="0.015" radius="0.02"/>
            </geometry>
            <material name="${caster_rviz_color}"/>
        </visual>

        <collision>
            <origin rpy="0 1.5707 1.5707" xyz="0.0 0 0.0"/>
            <geometry>
                <cylinder length="0.015" radius="0.02"/>
            </geometry>
        </collision>

        <inertial>
            <origin rpy="0 1.5707 1.5707" xyz="0.0 0 0.0"/>
            <mass value="0.05"/>
            <inertia ixx="5.9375e-06" ixy="0.0" ixz="0.0" iyy="5.9375e-06" iyz="0.0" izz="1e-05"/>
        </inertial>
    </link>

    <joint name="front_yaw_joint" type="continuous">
        <origin rpy="0 0 0" xyz="0.13 0 -0.079"/>
        <parent link="main_body_link"/>
        <child link="front_yaw_link"/>
        <axis xyz="0 0 1"/>
    </joint>

    <gazebo reference="front_yaw_link">
        <material>${caster_gazebo_color}</material>
    </gazebo>

    <link name="front_roll_link">
        <visual>
            <origin rpy="0 1.5707 1.5707" xyz="0 0 0"/>
            <geometry>
                <cylinder length="0.015" radius="0.02"/>
            </geometry>
            <material name="${caster_rviz_color}"/>
        </visual>

        <collision>
            <origin rpy="0 1.5707 1.5707" xyz="0 0 0"/>
            <geometry>
                <cylinder length="0.015" radius="0.02"/>
            </geometry>
        </collision>

        <inertial>
            <origin rpy="0 1.5707 1.5707" xyz="0 0 0"/>
            <mass value="0.05"/>
            <inertia ixx="5.9375e-06" ixy="0.0" ixz="0.0" iyy="5.9375e-06" iyz="0.0" izz="1e-05"/>
        </inertial>
    </link>

    <joint name="front_roll_joint" type="continuous">
        <origin rpy="0 0 0" xyz="0 0 0"/>
        <parent link="front_yaw_link"/>
        <child link="front_roll_link"/>
        <axis xyz="1 0 0"/>
    </joint>

    <gazebo reference="front_roll_link">
        <material>${caster_gazebo_color}</material>
    </gazebo>


    <link name="front_pitch_link">
        <visual>
            <origin rpy="0 1.5707 1.5707" xyz="0 0 0"/>
            <geometry>
                <sphere radius="0.025"/>
            </geometry>
            <material name="${caster_rviz_color}"/>
        </visual>

        <collision>
            <origin rpy="0 1.5707 1.5707" xyz="0 0 0"/>
            <geometry>
                <sphere radius="0.025"/>
            </geometry>
        </collision>

        <inertial>
            <origin rpy="0 1.5707 1.5707" xyz="0 0 0"/>
            <mass value="0.05"/>
            <inertia ixx="1.2500000000000002e-05" ixy="0.0" ixz="0.0" iyy="1.2500000000000002e-05" iyz="0.0" izz="1.2500000000000002e-05"/>
        </inertial>
    </link>

    <gazebo reference="front_pitch_link">
        <kp>1000000000000000000000000000.0</kp>
        <kd>1000000000000000000000000000.0</kd>
        <mu1>0.5</mu1>
        <mu2>0.5</mu2>
        <material>${caster_gazebo_color}</material>
    </gazebo>

    <joint name="front_pitch_joint" type="continuous">
        <origin rpy="0 0 0" xyz="0 0 0"/>
        <parent link="front_roll_link"/>
        <child link="front_pitch_link"/>
        <axis xyz="0 1 0"/>
    </joint>

    <!-- Caster Wheel Back -->
    <link name="back_yaw_link">
        <visual>
            <origin rpy="0 1.5707 1.5707" xyz="0.0 0.0 0.0"/>
            <geometry>
                <cylinder length="0.015" radius="0.02"/>
            </geometry>
            <material name="${caster_rviz_color}"/>
        </visual>

        <collision>
            <origin rpy="0 1.5707 1.5707" xyz="0.0 0.0 0.0"/>
            <geometry>
                <cylinder length="0.015" radius="0.02"/>
            </geometry>
        </collision>

        <inertial>
            <origin rpy="0 1.5707 1.5707" xyz="0.0 0.0 0.0"/>
            <mass value="0.05"/>
            <inertia ixx="5.9375e-06" ixy="0.0" ixz="0.0" iyy="5.9375e-06" iyz="0.0" izz="1e-05"/>
        </inertial>
    </link>

    <joint name="back_yaw_joint" type="continuous">
        <origin rpy="0 0 0" xyz="-0.13 0 -0.079"/>
        <parent link="main_body_link"/>
        <child link="back_yaw_link"/>
        <axis xyz="0 0 1"/>
    </joint>

    <gazebo reference="back_yaw_link">
        <material>${caster_gazebo_color}</material>
    </gazebo>

    <link name="back_roll_link">
        <visual>
            <origin rpy="0 1.5707 1.5707" xyz="0 0 0"/>
            <geometry>
                <cylinder length="0.015" radius="0.02"/>
            </geometry>
            <material name="${caster_rviz_color}"/>
        </visual>

        <collision>
            <origin rpy="0 1.5707 1.5707" xyz="0 0 0"/>
            <geometry>
                <cylinder length="0.015" radius="0.02"/>
            </geometry>
        </collision>

        <inertial>
            <origin rpy="0 1.5707 1.5707" xyz="0 0 0"/>
            <mass value="0.05"/>
            <inertia ixx="5.9375e-06" ixy="0.0" ixz="0.0" iyy="5.9375e-06" iyz="0.0" izz="1e-05"/>
        </inertial>
    </link>

    <joint name="back_roll_joint" type="continuous">
        <origin rpy="0 0 0" xyz="0 0 0"/>
        <parent link="back_yaw_link"/>
        <child link="back_roll_link"/>
        <axis xyz="1 0 0"/>
    </joint>

    <gazebo reference="back_roll_link">
        <material>${caster_gazebo_color}</material>
    </gazebo>


    <link name="back_pitch_link">
        <visual>
            <origin rpy="0 1.5707 1.5707" xyz="0 0 0"/>
            <geometry>
                <sphere radius="0.025"/>
            </geometry>
            <material name="${caster_rviz_color}"/>
        </visual>

        <collision>
            <origin rpy="0 1.5707 1.5707" xyz="0 0 0"/>
            <geometry>
                <sphere radius="0.025"/>
            </geometry>
        </collision>

        <inertial>
            <origin rpy="0 1.5707 1.5707" xyz="0 0 0"/>
            <mass value="0.05"/>
            <inertia ixx="1.2500000000000002e-05" ixy="0.0" ixz="0.0" iyy="1.2500000000000002e-05" iyz="0.0" izz="1.2500000000000002e-05"/>
        </inertial>
    </link>

    <gazebo reference="back_pitch_link">
        <kp>1000000000000000000000000000.0</kp>
        <kd>1000000000000000000000000000.0</kd>
        <mu1>0.5</mu1>
        <mu2>0.5</mu2>
        <material>${caster_gazebo_color}</material>
    </gazebo>

    <joint name="back_pitch_joint" type="continuous">
        <origin rpy="0 0 0" xyz="0 0 0"/>
        <parent link="back_roll_link"/>
        <child link="back_pitch_link"/>
        <axis xyz="0 1 0"/>
    </joint>

    <!-- laser_scanner -->
    <link name="laser_scanner_model">
        <visual>
            <origin rpy="0 0 0" xyz="0 0 0"/>
            <geometry>
                <mesh filename="package://barista_robot_description/meshes/hokuyo_urg_04lx.dae"/>
            </geometry>
            <material name="light_gray"/>
        </visual>

        <collision>
            <origin rpy="0 0 0" xyz="0 0 0"/>
            <geometry>
                <box size="0.05 0.05 0.07"/>
            </geometry>
        </collision>

        <inertial>
            <mass value="0.160"/>
            <origin rpy="0 0 0" xyz="0 0 0"/>
            <inertia ixx="9.866666666666669e-05" ixy="0.0" ixz="0.0" iyy="9.866666666666669e-05" iyz="0.0" izz="6.666666666666668e-05"/>
        </inertial>

    </link>

    <gazebo reference="laser_scanner_model">
        <material>Gazebo/Gray</material>
    </gazebo>

    <joint name="laser_frame_joint" type="fixed">
        <origin xyz="0.1 0.0 0.0775" rpy="0 0 0"/>
        <parent link="main_body_link"/>
        <child link="laser_scanner_model"/>
    </joint>


    <link name="laser_scan_frame">
    </link>

    <joint name="laser_scan_frame_joint" type="fixed">
        <origin rpy="0 0 0" xyz="0 0 0.055"/>
        <parent link="laser_scanner_model"/>
        <child link="laser_scan_frame"/>
        <axis xyz="0 0 0"/>
    </joint>


    <!-- PLUGINS -->
    <!-- JOINT PUBLISHER -->
    <gazebo>
        <plugin name="barista_gazebo_robot_joint_state" filename="libgazebo_ros_joint_state_publisher.so">
            <ros>
                <remapping>~/out:=joint_states</remapping>
            </ros>
            <update_rate>30</update_rate>

            <joint_name>left_wheel_joint</joint_name>
            <joint_name>right_wheel_joint</joint_name>
            <joint_name>front_yaw_joint</joint_name>
            <joint_name>back_yaw_joint</joint_name>
            <joint_name>front_roll_joint</joint_name>
            <joint_name>back_roll_joint</joint_name>
            <joint_name>front_pitch_joint</joint_name>
            <joint_name>back_pitch_joint</joint_name>
        </plugin>
    </gazebo>

    <!-- Differential drive -->
    <gazebo>
        <plugin filename="libgazebo_ros_diff_drive.so" name="differential_drive_controller">

            <!-- wheels -->
            <left_joint>left_wheel_joint</left_joint>
            <right_joint>right_wheel_joint</right_joint>

            <!-- kinematics -->
            <wheel_separation>0.2952</wheel_separation>
            <wheel_diameter>0.0704</wheel_diameter>

            <!-- limits -->
            <max_wheel_torque>200.0</max_wheel_torque>
            <max_wheel_acceleration>10.0</max_wheel_acceleration>

            <!-- input -->
            <!--<command_topic>cmd_vel</command_topic>-->

            <odometry_topic>odom</odometry_topic>
            <odometry_frame>odom</odometry_frame>
            <robot_base_frame>base_link</robot_base_frame>

            <!-- output -->
            <publish_odom>true</publish_odom>
            <publish_odom_tf>true</publish_odom_tf>
            <!--<publish_wheel_tf>true</publish_wheel_tf>-->

        </plugin>
    </gazebo>


   <!-- Sensors (with plugins) -->
  <!-- Laser scanner (simulated) -->
    <gazebo reference="laser_scan_frame">
        <sensor type="ray" name="sensor_ray">
            <always_on>true</always_on>
            <pose>0 0 0 0 0 0</pose>
            <visualize>false</visualize>
            <update_rate>10.0</update_rate>
            <ray>
                <scan>
                    <horizontal>
                        <samples>200</samples>
                        <resolution>1</resolution>
                        <min_angle>-3.1415</min_angle>
                        <max_angle>3.1415</max_angle>
                    </horizontal>
                </scan>
                <range>
                    <min>0.10</min>
                    <max>30.0</max>
                    <resolution>0.01</resolution>
                </range>
                <noise>
                    <type>gaussian</type>
                    <mean>0.0</mean>
                    <stddev>0.01</stddev>
                </noise>
            </ray>
            <plugin name="barista_laser_info" filename="libgazebo_ros_ray_sensor.so">
                <ros>
                    <remapping>~/out:=/scan</remapping>
                </ros>
                <output_type>sensor_msgs/LaserScan</output_type>
                <frame_name>laser_scan_frame</frame_name>
            </plugin>
        </sensor>
    </gazebo>

</robot>
